Workbook

Sheet RAB_Otomatis
A1: RENCANA ANGGARAN BIAYA (RAB) OTOMATIS
A2: Pilih 'Kode AHSP' dari dropdown. Harga akan terisi otomatis dari Daftar AHSP.
A4: No | B4: Kode AHSP (PILIH) | C4: Uraian Pekerjaan | D4: Sat | E4: Volume | F4: Harga Upah | G4: Harga Bahan | H4: Harga Alat | I4: Harga Satuan Total | J4: Jumlah Harga (Rp)
A5: 1 | B5: 1.1.1.1 | C5: =IF(ISBLANK(B5),"",VLOOKUP(B5,Daftar_AHSP!$B$4:$H$2596,2,FALSE)) -> Pembuatan 1 m’ pagar sementara dari kayu tinggi 2 meter | D5: =IF(ISBLANK(B5),"",VLOOKUP(B5,Daftar_AHSP!$B$4:$H$2596,3,FALSE)) -> m' | E5: 100 | F5: =IF(ISBLANK(B5),0,VLOOKUP(B5,Daftar_AHSP!$B$4:$H$2596,4,FALSE)*E5) -> 12760000 | G5: =IF(ISBLANK(B5),0,VLOOKUP(B5,Daftar_AHSP!$B$4:$H$2596,5,FALSE)*E5) -> 58821563 | H5: =IF(ISBLANK(B5),0,VLOOKUP(B5,Daftar_AHSP!$B$4:$H$2596,6,FALSE)*E5) -> 0 | I5: =IF(ISBLANK(B5),0,VLOOKUP(B5,Daftar_AHSP!$B$4:$H$2596,7,FALSE)) -> 787397 | J5: =IF(ISNUMBER(E5),E5*I5,0) -> 78739700
A6: 2 | B6: 1.2.1.1.1 | C6: =IF(ISBLANK(B6),"",VLOOKUP(B6,Daftar_AHSP!$B$4:$H$2596,2,FALSE)) -> Penggalian 1 m3 tanah biasa sedalam 0 s.d. 1 m untuk volume s.d. 200 m3 secara manual | D6: =IF(ISBLANK(B6),"",VLOOKUP(B6,Daftar_AHSP!$B$4:$H$2596,3,FALSE)) -> m3 | E6: 45 | F6: =IF(ISBLANK(B6),0,VLOOKUP(B6,Daftar_AHSP!$B$4:$H$2596,4,FALSE)*E6) -> 0 | G6: =IF(ISBLANK(B6),0,VLOOKUP(B6,Daftar_AHSP!$B$4:$H$2596,5,FALSE)*E6) -> 0 | H6: =IF(ISBLANK(B6),0,VLOOKUP(B6,Daftar_AHSP!$B$4:$H$2596,6,FALSE)*E6) -> 0 | I6: =IF(ISBLANK(B6),0,VLOOKUP(B6,Daftar_AHSP!$B$4:$H$2596,7,FALSE)) -> 90860 | J6: =IF(ISNUMBER(E6),E6*I6,0) -> 4088700
A7: 3 | C7: =IF(ISBLANK(B7),"",VLOOKUP(B7,Daftar_AHSP!$B$4:$H$2596,2,FALSE)) | D7: =IF(ISBLANK(B7),"",VLOOKUP(B7,Daftar_AHSP!$B$4:$H$2596,3,FALSE)) | F7: =IF(ISBLANK(B7),0,VLOOKUP(B7,Daftar_AHSP!$B$4:$H$2596,4,FALSE)*E7) -> 0 | G7: =IF(ISBLANK(B7),0,VLOOKUP(B7,Daftar_AHSP!$B$4:$H$2596,5,FALSE)*E7) -> 0 | H7: =IF(ISBLANK(B7),0,VLOOKUP(B7,Daftar_AHSP!$B$4:$H$2596,6,FALSE)*E7) -> 0 | I7: =IF(ISBLANK(B7),0,VLOOKUP(B7,Daftar_AHSP!$B$4:$H$2596,7,FALSE)) -> 0 | J7: =IF(ISNUMBER(E7),E7*I7,0) -> 0
A8: 4 | C8: =IF(ISBLANK(B8),"",VLOOKUP(B8,Daftar_AHSP!$B$4:$H$2596,2,FALSE)) | D8: =IF(ISBLANK(B8),"",VLOOKUP(B8,Daftar_AHSP!$B$4:$H$2596,3,FALSE)) | F8: =IF(ISBLANK(B8),0,VLOOKUP(B8,Daftar_AHSP!$B$4:$H$2596,4,FALSE)*E8) -> 0 | G8: =IF(ISBLANK(B8),0,VLOOKUP(B8,Daftar_AHSP!$B$4:$H$2596,5,FALSE)*E8) -> 0 | H8: =IF(ISBLANK(B8),0,VLOOKUP(B8,Daftar_AHSP!$B$4:$H$2596,6,FALSE)*E8) -> 0 | I8: =IF(ISBLANK(B8),0,VLOOKUP(B8,Daftar_AHSP!$B$4:$H$2596,7,FALSE)) -> 0 | J8: =IF(ISNUMBER(E8),E8*I8,0) -> 0
A9: 5 | C9: =IF(ISBLANK(B9),"",VLOOKUP(B9,Daftar_AHSP!$B$4:$H$2596,2,FALSE)) | D9: =IF(ISBLANK(B9),"",VLOOKUP(B9,Daftar_AHSP!$B$4:$H$2596,3,FALSE)) | F9: =IF(ISBLANK(B9),0,VLOOKUP(B9,Daftar_AHSP!$B$4:$H$2596,4,FALSE)*E9) -> 0 | G9: =IF(ISBLANK(B9),0,VLOOKUP(B9,Daftar_AHSP!$B$4:$H$2596,5,FALSE)*E9) -> 0 | H9: =IF(ISBLANK(B9),0,VLOOKUP(B9,Daftar_AHSP!$B$4:$H$2596,6,FALSE)*E9) -> 0 | I9: =IF(ISBLANK(B9),0,VLOOKUP(B9,Daftar_AHSP!$B$4:$H$2596,7,FALSE)) -> 0 | J9: =IF(ISNUMBER(E9),E9*I9,0) -> 0
A10: 6 | C10: =IF(ISBLANK(B10),"",VLOOKUP(B10,Daftar_AHSP!$B$4:$H$2596,2,FALSE)) | D10: =IF(ISBLANK(B10),"",VLOOKUP(B10,Daftar_AHSP!$B$4:$H$2596,3,FALSE)) | F10: =IF(ISBLANK(B10),0,VLOOKUP(B10,Daftar_AHSP!$B$4:$H$2596,4,FALSE)*E10) -> 0 | G10: =IF(ISBLANK(B10),0,VLOOKUP(B10,Daftar_AHSP!$B$4:$H$2596,5,FALSE)*E10) -> 0 | H10: =IF(ISBLANK(B10),0,VLOOKUP(B10,Daftar_AHSP!$B$4:$H$2596,6,FALSE)*E10) -> 0 | I10: =IF(ISBLANK(B10),0,VLOOKUP(B10,Daftar_AHSP!$B$4:$H$2596,7,FALSE)) -> 0 | J10: =IF(ISNUMBER(E10),E10*I10,0) -> 0
A11: 7 | C11: =IF(ISBLANK(B11),"",VLOOKUP(B11,Daftar_AHSP!$B$4:$H$2596,2,FALSE)) | D11: =IF(ISBLANK(B11),"",VLOOKUP(B11,Daftar_AHSP!$B$4:$H$2596,3,FALSE)) | F11: =IF(ISBLANK(B11),0,VLOOKUP(B11,Daftar_AHSP!$B$4:$H$2596,4,FALSE)*E11) -> 0 | G11: =IF(ISBLANK(B11),0,VLOOKUP(B11,Daftar_AHSP!$B$4:$H$2596,5,FALSE)*E11) -> 0 | H11: =IF(ISBLANK(B11),0,VLOOKUP(B11,Daftar_AHSP!$B$4:$H$2596,6,FALSE)*E11) -> 0 | I11: =IF(ISBLANK(B11),0,VLOOKUP(B11,Daftar_AHSP!$B$4:$H$2596,7,FALSE)) -> 0 | J11: =IF(ISNUMBER(E11),E11*I11,0) -> 0
A12: 8 | C12: =IF(ISBLANK(B12),"",VLOOKUP(B12,Daftar_AHSP!$B$4:$H$2596,2,FALSE)) | D12: =IF(ISBLANK(B12),"",VLOOKUP(B12,Daftar_AHSP!$B$4:$H$2596,3,FALSE)) | F12: =IF(ISBLANK(B12),0,VLOOKUP(B12,Daftar_AHSP!$B$4:$H$2596,4,FALSE)*E12) -> 0 | G12: =IF(ISBLANK(B12),0,VLOOKUP(B12,Daftar_AHSP!$B$4:$H$2596,5,FALSE)*E12) -> 0 | H12: =IF(ISBLANK(B12),0,VLOOKUP(B12,Daftar_AHSP!$B$4:$H$2596,6,FALSE)*E12) -> 0 | I12: =IF(ISBLANK(B12),0,VLOOKUP(B12,Daftar_AHSP!$B$4:$H$2596,7,FALSE)) -> 0 | J12: =IF(ISNUMBER(E12),E12*I12,0) -> 0
A13: 9 | C13: =IF(ISBLANK(B13),"",VLOOKUP(B13,Daftar_AHSP!$B$4:$H$2596,2,FALSE)) | D13: =IF(ISBLANK(B13),"",VLOOKUP(B13,Daftar_AHSP!$B$4:$H$2596,3,FALSE)) | F13: =IF(ISBLANK(B13),0,VLOOKUP(B13,Daftar_AHSP!$B$4:$H$2596,4,FALSE)*E13) -> 0 | G13: =IF(ISBLANK(B13),0,VLOOKUP(B13,Daftar_AHSP!$B$4:$H$2596,5,FALSE)*E13) -> 0 | H13: =IF(ISBLANK(B13),0,VLOOKUP(B13,Daftar_AHSP!$B$4:$H$2596,6,FALSE)*E13) -> 0 | I13: =IF(ISBLANK(B13),0,VLOOKUP(B13,Daftar_AHSP!$B$4:$H$2596,7,FALSE)) -> 0 | J13: =IF(ISNUMBER(E13),E13*I13,0) -> 0
A14: 10 | C14: =IF(ISBLANK(B14),"",VLOOKUP(B14,Daftar_AHSP!$B$4:$H$2596,2,FALSE)) | D14: =IF(ISBLANK(B14),"",VLOOKUP(B14,Daftar_AHSP!$B$4:$H$2596,3,FALSE)) | F14: =IF(ISBLANK(B14),0,VLOOKUP(B14,Daftar_AHSP!$B$4:$H$2596,4,FALSE)*E14) -> 0 | G14: =IF(ISBLANK(B14),0,VLOOKUP(B14,Daftar_AHSP!$B$4:$H$2596,5,FALSE)*E14) -> 0 | H14: =IF(ISBLANK(B14),0,VLOOKUP(B14,Daftar_AHSP!$B$4:$H$2596,6,FALSE)*E14) -> 0 | I14: =IF(ISBLANK(B14),0,VLOOKUP(B14,Daftar_AHSP!$B$4:$H$2596,7,FALSE)) -> 0 | J14: =IF(ISNUMBER(E14),E14*I14,0) -> 0
A15: 11 | C15: =IF(ISBLANK(B15),"",VLOOKUP(B15,Daftar_AHSP!$B$4:$H$2596,2,FALSE)) | D15: =IF(ISBLANK(B15),"",VLOOKUP(B15,Daftar_AHSP!$B$4:$H$2596,3,FALSE)) | F15: =IF(ISBLANK(B15),0,VLOOKUP(B15,Daftar_AHSP!$B$4:$H$2596,4,FALSE)*E15) -> 0 | G15: =IF(ISBLANK(B15),0,VLOOKUP(B15,Daftar_AHSP!$B$4:$H$2596,5,FALSE)*E15) -> 0 | H15: =IF(ISBLANK(B15),0,VLOOKUP(B15,Daftar_AHSP!$B$4:$H$2596,6,FALSE)*E15) -> 0 | I15: =IF(ISBLANK(B15),0,VLOOKUP(B15,Daftar_AHSP!$B$4:$H$2596,7,FALSE)) -> 0 | J15: =IF(ISNUMBER(E15),E15*I15,0) -> 0
A16: 12 | C16: =IF(ISBLANK(B16),"",VLOOKUP(B16,Daftar_AHSP!$B$4:$H$2596,2,FALSE)) | D16: =IF(ISBLANK(B16),"",VLOOKUP(B16,Daftar_AHSP!$B$4:$H$2596,3,FALSE)) | F16: =IF(ISBLANK(B16),0,VLOOKUP(B16,Daftar_AHSP!$B$4:$H$2596,4,FALSE)*E16) -> 0 | G16: =IF(ISBLANK(B16),0,VLOOKUP(B16,Daftar_AHSP!$B$4:$H$2596,5,FALSE)*E16) -> 0 | H16: =IF(ISBLANK(B16),0,VLOOKUP(B16,Daftar_AHSP!$B$4:$H$2596,6,FALSE)*E16) -> 0 | I16: =IF(ISBLANK(B16),0,VLOOKUP(B16,Daftar_AHSP!$B$4:$H$2596,7,FALSE)) -> 0 | J16: =IF(ISNUMBER(E16),E16*I16,0) -> 0
A17: 13 | C17: =IF(ISBLANK(B17),"",VLOOKUP(B17,Daftar_AHSP!$B$4:$H$2596,2,FALSE)) | D17: =IF(ISBLANK(B17),"",VLOOKUP(B17,Daftar_AHSP!$B$4:$H$2596,3,FALSE)) | F17: =IF(ISBLANK(B17),0,VLOOKUP(B17,Daftar_AHSP!$B$4:$H$2596,4,FALSE)*E17) -> 0 | G17: =IF(ISBLANK(B17),0,VLOOKUP(B17,Daftar_AHSP!$B$4:$H$2596,5,FALSE)*E17) -> 0 | H17: =IF(ISBLANK(B17),0,VLOOKUP(B17,Daftar_AHSP!$B$4:$H$2596,6,FALSE)*E17) -> 0 | I17: =IF(ISBLANK(B17),0,VLOOKUP(B17,Daftar_AHSP!$B$4:$H$2596,7,FALSE)) -> 0 | J17: =IF(ISNUMBER(E17),E17*I17,0) -> 0
A18: 14 | C18: =IF(ISBLANK(B18),"",VLOOKUP(B18,Daftar_AHSP!$B$4:$H$2596,2,FALSE)) | D18: =IF(ISBLANK(B18),"",VLOOKUP(B18,Daftar_AHSP!$B$4:$H$2596,3,FALSE)) | F18: =IF(ISBLANK(B18),0,VLOOKUP(B18,Daftar_AHSP!$B$4:$H$2596,4,FALSE)*E18) -> 0 | G18: =IF(ISBLANK(B18),0,VLOOKUP(B18,Daftar_AHSP!$B$4:$H$2596,5,FALSE)*E18) -> 0 | H18: =IF(ISBLANK(B18),0,VLOOKUP(B18,Daftar_AHSP!$B$4:$H$2596,6,FALSE)*E18) -> 0 | I18: =IF(ISBLANK(B18),0,VLOOKUP(B18,Daftar_AHSP!$B$4:$H$2596,7,FALSE)) -> 0 | J18: =IF(ISNUMBER(E18),E18*I18,0) -> 0
... A54: 50 | C54: =IF(ISBLANK(B54),"",VLOOKUP(B54,Daftar_AHSP!$B$4:$H$2596,2,FALSE)) | D54: =IF(ISBLANK(B54),"",VLOOKUP(B54,Daftar_AHSP!$B$4:$H$2596,3,FALSE)) | F54: =IF(ISBLANK(B54),0,VLOOKUP(B54,Daftar_AHSP!$B$4:$H$2596,4,FALSE)*E54) -> 0 | G54: =IF(ISBLANK(B54),0,VLOOKUP(B54,Daftar_AHSP!$B$4:$H$2596,5,FALSE)*E54) -> 0 | H54: =IF(ISBLANK(B54),0,VLOOKUP(B54,Daftar_AHSP!$B$4:$H$2596,6,FALSE)*E54) -> 0 | I54: =IF(ISBLANK(B54),0,VLOOKUP(B54,Daftar_AHSP!$B$4:$H$2596,7,FALSE)) -> 0 | J54: =IF(ISNUMBER(E54),E54*I54,0) -> 0
A55: TOTAL BIAYA KONSTRUKSI | J55: =SUM(J5:J54) -> 82828400

Sheet Daftar_AHSP
A1: DAFTAR HARGA SATUAN PEKERJAAN (AHSP CIPTA KARYA 2025)
A3: No | B3: Kode AHSP | C3: Uraian Pekerjaan | D3: Satuan | E3: Subtotal UPAH (Rp) | F3: Subtotal BAHAN (Rp) | G3: Subtotal ALAT (Rp) | H3: Harga Satuan Total (Rp)
A4: 1 | B4: 1.1 | C4: PEKERJAAN PERSIAPAN
A5: 2 | B5: 1.1.1 | C5: Pembuatan Pagar Proyek
A6: 3 | B6: 1.1.1.1 | C6: Pembuatan 1 m’ pagar sementara dari kayu tinggi 2 meter | D6: m' | E6: 127600 | F6: 588215.63 | G6: 0 | H6: 787397
A7: 4 | B7: 1.1.1.2 | C7: Pembuatan 1 m’ pagar sementara dari seng gelombang rangka kayu tinggi 2 meter | D7: m' | E7: 67225 | F7: 510526.79 | G7: 0 | H7: 635526
A8: 5 | B8: 1.1.1.3 | C8: Pembuatan 1 m’ pagar sementara dari kawat duri tinggi 2 meter | D8: m' | E8: 82885 | F8: 260969.45 | G8: 0 | H8: 378239
A9: 6 | B9: 1.1.1.4 | C9: Pembuatan 1 m’ pagar sementara seng gelombang rangka baja L.40.40.4 tinggi pagar 1.8 meter | D9: m' | E9: 53000 | F9: 336915 | G9: 0 | H9: 428906
A10: 7 | B10: 1.1.1.5 | C10: Pembuatan 1 m2 pagar BRC Galvanis | D10: m2 | E10: 10900 | F10: 4947 | G10: 0 | H10: 17431
A11: 8 | B11: 1.1.1.6 | C11: Pemasangan 1 m2 panel beton pracetak 50x50x240 untuk pagar | D11: m2 | E11: 0 | F11: 0 | G11: 0 | H11: 484982
A12: 9 | B12: 1.1.2 | C12: Alat dan/atau sarana penunjang
A13: 10 | B13: 1.1.2.1 | C13: 1 buah papan nama pekerjaan ukuran 0.8x1.2 menggunakan multiflex 18 mm, frame besi siku dan tiang kayu 8/12 | D13: buah | E13: 0 | F13: 0 | G13: 0 | H13: 1909085
A14: 11 | B14: 1.1.2.2 | C14: 1 buah papan nama pekerjaan ukuran 0.6x08 menggunakan multiplex 10 mm, frame allumunium siku dan tiang kayu 5/7, printing banner plastik | D14: buah | E14: 0 | F14: 0 | G14: 0 | H14: 702576
A15: 12 | B15: 1.1.2.3 | C15: Pembuatan 1 m2 kantor sementara/rumah jaga/gudang semen dan peralatan lantai plesteran, dinding setengah tembok | D15: m2 | E15: 707500 | F15: 2475485 | G15: 0 | H15: 3501283
A16: 13 | B16: 1.1.2.4 | C16: Pembuatan 1 m2 direksi keet (Kantor), los kerja dan gudang | D16: m2 | E16: 209000 | F16: 4972535 | G16: 0 | H16: 5699688
A17: 14 | B17: 1.1.2.5 | C17: Pembuatan 1 m2 jalan sementara lapis macadam | D17: m2 | E17: 28642.5 | F17: 654584 | G17: 560772.38 | H17: 1368398
A18: 15 | B18: 1.1.2.6 | C18: Pembuatan 1 m2 jalan sementara (Jalan Tanah) | D18: m2 | E18: 0 | F18: 0 | G18: 0 | H18: 1281336
A19: 16 | B19: 1.1.2.7 | C19: Pembuatan 1 m2 jalan sementara (Jalan Kerikil) | D19: m2 | E19: 0 | F19: 0 | G19: 0 | H19: 1343259
A20: 17 | B20: 1.1.3 | C20: Pembersihan dan Pengupasan Permukaan Tanah
A21: 18 | B21: 1.1.3.1 | C21: 1 m3 Pembersihan dan pengupasan permukaan tanah (striping) s.d. tanaman ∅ 2 cm | D21: m2 | E21: 0 | F21: 0 | G21: 0 | H21: 12100
A22: 19 | B22: 1.1.3.2 | C22: Tebas tebang 1 m2 tanaman/tumbuhan ∅ < 5 cm | D22: m2 | E22: 3600 | F22: 0 | G22: 0 | H22: 3960
A23: 20 | B23: 1.1.3.3. | C23: Tebas tebang 1 m 2 tanaman/tumbuhan ∅ >5 s.d. 15 cm | D23: m2 | E23: 0 | F23: 0 | G23: 0 | H23: 6600
A24: 21 | B24: 1.1.3.4 | C24: Tebas tebang 1 batang pohon/tumbuhan ∅ >15 s.d. 30 cm | D24: btg | E24: 0 | F24: 0 | G24: 0 | H24: 22341
A25: 22 | B25: 1.1.3.5 | C25: Tebas tebang 1 batang pohon/tumbuhan ∅ > 30 s.d 50 cm | D25: btg | E25: 1440 | F25: 0 | G25: 18750 | H25: 22209
A26: 23 | B26: 1.1.3.6 | C26: Tebas tebang 1 batang pohon/tumbuhan ∅ > 50 s.d 75 cm (diameter pohon diukur 1 m di atas permukaan tanah) | D26: btg | E26: 0 | F26: 0 | G26: 0 | H26: 48840
A27: 24 | B27: 1.1.3.7 | C27: Tebas tebang 1 batang pohon/tumbuhan ∅ > 75 cm (diameter pohon diukur 1 m di atas permukaan tanah) | D27: btg | E27: 30000 | F27: 0 | G27: 27000 | H27: 62700
A28: 25 | B28: 1.1.3.8 | C28: Gali dan cabut 1 tunggul pohon tanaman keras ∅ > 5 s.d. 15 cm (termasuk pembuangan sisa tunggul tanpa menutup kembali bekas lubang) | D28: tgl | E28: 17150 | F28: 0 | G28: 27000 | H28: 48565
A29: 26 | B29: 1.1.3.9 | C29: Gali dan cabut 1 tunggul pohon tanaman keras ∅ > 15 cm s.d. 30 cm (termasuk pembuangan sisa tunggul tanpa menutup kembali bekas lubang) | D29: tgl | E29: 20110 | F29: 0 | G29: 42000 | H29: 68321
A30: 27 | B30: 1.1.3.10 | C30: Gali dan cabut 1 tunggul pohon tanaman keras ∅ > 30 cm s.d. 50 cm (termasuk pembuangan sisa tunggul tanpa menutup kembali bekas lubang) | D30: tgl | E30: 21890 | F30: 0 | G30: 66000 | H30: 96679
A31: 28 | B31: 1.1.3.11 | C31: Gali dan cabut 1 tunggul pohon tanaman keras ∅ > 50 cm s.d. 75 cm (termasuk pembuangan sisa tunggul tanpa menutup kembali bekas lubang) | D31: tgl | E31: 0 | F31: 0 | G31: 0 | H31: 149985
A32: 29 | B32: 1.1.3.12 | C32: Gali dan cabut 1 tunggul pohon tanaman keras ∅ > 75 cm (termasuk pembuangan sisa tunggul tanpa menutup kembali bekas lubang) | D32: tgl | E32: 41190 | F32: 0 | G32: 157200 | H32: 218229
... A37: 34 | B37: 1.1.3.17 | C37: Gali dan cabut 1 tunggul pohon tanaman keras ∅ > 75 cm (termasuk pembuangan sisa tunggul dengan menutup kembali bekas lubang) | D37: m' | E37: 90000 | F37: 0 | G37: 157200 | H37: 271920
A38: 35 | B38: 1.1.4 | C38: Pengukuran dan Pasangan Bouwplank
A39: 36 | B39: 1.1.4.1 | C39: Pengukuran ulang topografi seluas 1 Ha | D39: Ha | E39: 1193750 | F39: 1560423.9 | G39: 225000 | H39: 3277091
A40: 37 | B40: 1.1.4.2 | C40: Pasangan 1 m' bouwplank | D40: m' | E40: 2415 | F40: 152919.6 | G40: 600 | H40: 171528
A41: 38 | B41: 1.1.4.3 | C41: Patok Kayu (kaso5/7) Panjang 0,5 m' | D41: m' | E41: 1610 | F41: 171933.6 | G41: 400 | H41: 191337
A42: 39 | B42: 1.1.4.4 | C42: 1 Buah Patok Kayu (Kaso 5/7) panjang 1 m' | D42: m' | E42: 2415 | F42: 74898.7 | G42: 450 | H42: 85540
A43: 40 | B43: 1.1.4.5 | C43: Patok Tetap Bantu (PTB) | D43: m' | E43: 81797.613 | F43: 49350 | G43: 0 | H43: 144262
A44: 41 | B44: 1.1.4.6 | C44: Patok Tetap Utama (PTU) | D44: m' | E44: 168621.28 | F44: 27594.5 | G44: 0 | H44: 215837
A45: 42 | B45: 1.2 | C45: PEKERJAAN GALIAN TANAH
...

Sheet Database_Harga
A1: DATABASE HARGA UPAH, BAHAN, DAN ALAT (CIPTA KARYA 2025)
A3: No | B3: Kode | C3: Nama Komponen | D3: Satuan | E3: Harga Satuan (Rp)
A4: NO | B4: Kode | C4: UPAH - MATERIAL - ALAT | D4: SATUAN
A5: 1 | C5: 2 | D5: 3 | E5: 4
A6: I. | C6: UPAH
A7: 1 | B7: L.01 | C7: Pekerja | D7: OH | E7: 100000
A8: 2 | B8: L.02 | C8: Tukang batu | D8: OH | E8: 145000
A9: 3 | B9: L.02 | C9: Tukang kayu | D9: OH | E9: 145000
A10: 4 | B10: L.02 | C10: Tukang besi | D10: OH | E10: 145000
A11: 5 | B11: L.02 | C11: Tukang cat | D11: OH | E11: 145000
B12: L.02 | C12: Tukang pelitur | D12: OH | E12: 145000
A13: 6 | B13: L.02 | C13: Tukang pipa | D13: OH | E13: 145000
A14: 7 | B14: L.02 | C14: Tukang penganyam bronjong | D14: OH | E14: 145000
A15: 8 | B15: L.02 | C15: Tukang tebas | D15: OH | E15: 145000
A16: 9 | B16: L.02 | C16: Tukang las | D16: OH | E16: 145000
A17: 10 | B17: L.02 | C17: Tukang las geotextile | D17: OH | E17: 145000
A18: 11 | B18: L.02 | C18: Tukang listrik | D18: OH | E18: 145000
A19: 12 | B19: L.02 | C19: Tukang alumunium | D19: OH | E19: 145000
A20: 13 | B20: L.02 | C20: Tukang kaca | D20: OH
A21: 14 | B21: L.02 | C21: Tukang erection | D21: OH | E21: 145000
A22: 15 | B22: L.02 | C22: Tukang tanam | D22: OH | E22: 145000
C23: Tukang Tanam | D23: OH | E23: 181250
C24: Kepala Tukang Tanam | D24: OH | E24: 218750
C25: Tukang pemelihara taman | D25: OH | E25: 145000
C26: Tukang pemelihara taman (115% Pekerja) | D26: OH | E26: 115000
A27: 10 | C27: Tukang gali | D27: OH | E27: 120000
A28: 11 | C28: Tukang aspal | D28: OH | E28: 120000
A29: 13 | B29: L.03 | C29: Kepala tukang | D29: OH | E29: 175000
A30: 14 | B30: L.04 | C30: Mandor | D30: OH | E30: 200000
A31: 21 | B31: L.05 | C31: Juru ukur | D31: OH | E31: 175000
A32: 28 | B32: L.06 | C32: Pembantu juru ukur | D32: OH | E32: 150000
A33: 24 | B33: L.07 | C33: Mekanik alat berat | D33: OH | E33: 220000
A34: 25 | B34: L.08 | C34: Operator alat berat | D34: OH | E34: 250000
A35: 30 | B35: L.09 | C35: Pembantu operator alat berat | D35: OH | E35: 130000
A36: 31 | B36: L.10 | C36: Sopir | D36: OH | E36: 200000
A37: 22 | B37: L.11 | C37: Kenek | D37: OH | E37: 135000
A38: 15 | C38: Administrasi bor | D38: OH | E38: 110000
A39: 16 | C39: Ahli geologist | D39: OH | E39: 400000
A40: 17 | C40: Ahli topografi | D40: OH | E40: 400000
A41: 18 | C41: Crew driller | D41: OH | E41: 125000
...

Sheet Analisa_Alat
A1: FORM ANALISA HARGA SATUAN ALAT
A2: No | B2: Uraian | C2: Kode | D2: Satuan | E2: Koefisien/Rumus | F2: Nilai (Rp)
A3: 1 | B3: Harga Pokok Alat | C3: A | D3: Rp | F3: 100000000
A4: 2 | B4: Umur Ekonomis | C4: W | D4: Tahun | F4: 5
A5: 3 | B5: Jam Kerja Per Tahun | C5: W_jam | D5: Jam | F5: 2000
A6: 4 | B6: Biaya Pasti (Penyusutan) | C6: E | D6: Rp | E6: =(A - 10%A)*15% / W_jam -> #ERROR! | F6: =(F3-(0.1*F3))*0.15 / F5 -> 6750
A7: 5 | B7: Biaya Operasi (BBM, Pelumas, Perawatan) | C7: K | D7: Rp | E7: Estimasi Manual | F7: 50000
A8: 6 | B8: Total Biaya Sewa per Jam | C8: Total | D8: Rp | E8: =E + K -> #NAME? | F8: =F6+F7 -> 56750
