Workbook

Sheet 1_Summary_RAB
B2: SUMMARY RENCANA ANGGARAN BIAYA & SMKK
B4: A. REKAPITULASI BIAYA
B5: 1. Total Biaya Konstruksi Murni | C5: ='2_RAB_Detail'!G35
B6: 2. Total Biaya K3 / SMKK (Manual Input jika ada) | C6: 0
B7: GRAND TOTAL BIAYA PROYEK | C7: =C5+C6
B8: TERBILANG: | C8: =Terbilang(C7) & " Rupiah"

Sheet 2_RAB_Detail
A1: RENCANA ANGGARAN BIAYA (RAB) MANUAL
A2: Ketik/Pilih Kode AHSP pada kolom B (Kuning), Harga Satuan akan ditarik secara otomatis!
A4: No | B4: Kode AHSP | C4: Uraian Pekerjaan | D4: Satuan | E4: Volume (Input) | F4: Harga Satuan (Rp) | G4: Jumlah Harga (Rp)
A5: 1 | B5: 1.2.1.1.1 | C5: =IF(ISBLANK(B5), "", IF(ISNA(VLOOKUP(B5,'3_Daftar_AHSP'!A:E,3,FALSE)), "Kode Salah", VLOOKUP(B5,'3_Daftar_AHSP'!A:E,3,FALSE))) | D5: =IF(ISBLANK(B5), "", IF(ISNA(VLOOKUP(B5,'3_Daftar_AHSP'!A:E,4,FALSE)), "", VLOOKUP(B5,'3_Daftar_AHSP'!A:E,4,FALSE))) | E5: 45 | F5: =IF(ISBLANK(B5), 0, IF(ISNA(VLOOKUP(B5,'3_Daftar_AHSP'!A:E,5,FALSE)), 0, VLOOKUP(B5,'3_Daftar_AHSP'!A:E,5,FALSE))) | G5: =IF(ISNUMBER(E5),E5*F5,0)
A6: 2 | C6: =IF(ISBLANK(B6), "", IF(ISNA(VLOOKUP(B6,'3_Daftar_AHSP'!A:E,3,FALSE)), "Kode Salah", VLOOKUP(B6,'3_Daftar_AHSP'!A:E,3,FALSE))) | D6: =IF(ISBLANK(B6), "", IF(ISNA(VLOOKUP(B6,'3_Daftar_AHSP'!A:E,4,FALSE)), "", VLOOKUP(B6,'3_Daftar_AHSP'!A:E,4,FALSE))) | F6: =IF(ISBLANK(B6), 0, IF(ISNA(VLOOKUP(B6,'3_Daftar_AHSP'!A:E,5,FALSE)), 0, VLOOKUP(B6,'3_Daftar_AHSP'!A:E,5,FALSE))) | G6: =IF(ISNUMBER(E6),E6*F6,0)
A7: 3 | C7: =IF(ISBLANK(B7), "", IF(ISNA(VLOOKUP(B7,'3_Daftar_AHSP'!A:E,3,FALSE)), "Kode Salah", VLOOKUP(B7,'3_Daftar_AHSP'!A:E,3,FALSE))) | D7: =IF(ISBLANK(B7), "", IF(ISNA(VLOOKUP(B7,'3_Daftar_AHSP'!A:E,4,FALSE)), "", VLOOKUP(B7,'3_Daftar_AHSP'!A:E,4,FALSE))) | F7: =IF(ISBLANK(B7), 0, IF(ISNA(VLOOKUP(B7,'3_Daftar_AHSP'!A:E,5,FALSE)), 0, VLOOKUP(B7,'3_Daftar_AHSP'!A:E,5,FALSE))) | G7: =IF(ISNUMBER(E7),E7*F7,0)
A8: 4 | C8: =IF(ISBLANK(B8), "", IF(ISNA(VLOOKUP(B8,'3_Daftar_AHSP'!A:E,3,FALSE)), "Kode Salah", VLOOKUP(B8,'3_Daftar_AHSP'!A:E,3,FALSE))) | D8: =IF(ISBLANK(B8), "", IF(ISNA(VLOOKUP(B8,'3_Daftar_AHSP'!A:E,4,FALSE)), "", VLOOKUP(B8,'3_Daftar_AHSP'!A:E,4,FALSE))) | F8: =IF(ISBLANK(B8), 0, IF(ISNA(VLOOKUP(B8,'3_Daftar_AHSP'!A:E,5,FALSE)), 0, VLOOKUP(B8,'3_Daftar_AHSP'!A:E,5,FALSE))) | G8: =IF(ISNUMBER(E8),E8*F8,0)
A9: 5 | C9: =IF(ISBLANK(B9), "", IF(ISNA(VLOOKUP(B9,'3_Daftar_AHSP'!A:E,3,FALSE)), "Kode Salah", VLOOKUP(B9,'3_Daftar_AHSP'!A:E,3,FALSE))) | D9: =IF(ISBLANK(B9), "", IF(ISNA(VLOOKUP(B9,'3_Daftar_AHSP'!A:E,4,FALSE)), "", VLOOKUP(B9,'3_Daftar_AHSP'!A:E,4,FALSE))) | F9: =IF(ISBLANK(B9), 0, IF(ISNA(VLOOKUP(B9,'3_Daftar_AHSP'!A:E,5,FALSE)), 0, VLOOKUP(B9,'3_Daftar_AHSP'!A:E,5,FALSE))) | G9: =IF(ISNUMBER(E9),E9*F9,0)
A10: 6 | C10: =IF(ISBLANK(B10), "", IF(ISNA(VLOOKUP(B10,'3_Daftar_AHSP'!A:E,3,FALSE)), "Kode Salah", VLOOKUP(B10,'3_Daftar_AHSP'!A:E,3,FALSE))) | D10: =IF(ISBLANK(B10), "", IF(ISNA(VLOOKUP(B10,'3_Daftar_AHSP'!A:E,4,FALSE)), "", VLOOKUP(B10,'3_Daftar_AHSP'!A:E,4,FALSE))) | F10: =IF(ISBLANK(B10), 0, IF(ISNA(VLOOKUP(B10,'3_Daftar_AHSP'!A:E,5,FALSE)), 0, VLOOKUP(B10,'3_Daftar_AHSP'!A:E,5,FALSE))) | G10: =IF(ISNUMBER(E10),E10*F10,0)
A11: 7 | C11: =IF(ISBLANK(B11), "", IF(ISNA(VLOOKUP(B11,'3_Daftar_AHSP'!A:E,3,FALSE)), "Kode Salah", VLOOKUP(B11,'3_Daftar_AHSP'!A:E,3,FALSE))) | D11: =IF(ISBLANK(B11), "", IF(ISNA(VLOOKUP(B11,'3_Daftar_AHSP'!A:E,4,FALSE)), "", VLOOKUP(B11,'3_Daftar_AHSP'!A:E,4,FALSE))) | F11: =IF(ISBLANK(B11), 0, IF(ISNA(VLOOKUP(B11,'3_Daftar_AHSP'!A:E,5,FALSE)), 0, VLOOKUP(B11,'3_Daftar_AHSP'!A:E,5,FALSE))) | G11: =IF(ISNUMBER(E11),E11*F11,0)
A12: 8 | C12: =IF(ISBLANK(B12), "", IF(ISNA(VLOOKUP(B12,'3_Daftar_AHSP'!A:E,3,FALSE)), "Kode Salah", VLOOKUP(B12,'3_Daftar_AHSP'!A:E,3,FALSE))) | D12: =IF(ISBLANK(B12), "", IF(ISNA(VLOOKUP(B12,'3_Daftar_AHSP'!A:E,4,FALSE)), "", VLOOKUP(B12,'3_Daftar_AHSP'!A:E,4,FALSE))) | F12: =IF(ISBLANK(B12), 0, IF(ISNA(VLOOKUP(B12,'3_Daftar_AHSP'!A:E,5,FALSE)), 0, VLOOKUP(B12,'3_Daftar_AHSP'!A:E,5,FALSE))) | G12: =IF(ISNUMBER(E12),E12*F12,0)
A13: 9 | C13: =IF(ISBLANK(B13), "", IF(ISNA(VLOOKUP(B13,'3_Daftar_AHSP'!A:E,3,FALSE)), "Kode Salah", VLOOKUP(B13,'3_Daftar_AHSP'!A:E,3,FALSE))) | D13: =IF(ISBLANK(B13), "", IF(ISNA(VLOOKUP(B13,'3_Daftar_AHSP'!A:E,4,FALSE)), "", VLOOKUP(B13,'3_Daftar_AHSP'!A:E,4,FALSE))) | F13: =IF(ISBLANK(B13), 0, IF(ISNA(VLOOKUP(B13,'3_Daftar_AHSP'!A:E,5,FALSE)), 0, VLOOKUP(B13,'3_Daftar_AHSP'!A:E,5,FALSE))) | G13: =IF(ISNUMBER(E13),E13*F13,0)
A14: 10 | C14: =IF(ISBLANK(B14), "", IF(ISNA(VLOOKUP(B14,'3_Daftar_AHSP'!A:E,3,FALSE)), "Kode Salah", VLOOKUP(B14,'3_Daftar_AHSP'!A:E,3,FALSE))) | D14: =IF(ISBLANK(B14), "", IF(ISNA(VLOOKUP(B14,'3_Daftar_AHSP'!A:E,4,FALSE)), "", VLOOKUP(B14,'3_Daftar_AHSP'!A:E,4,FALSE))) | F14: =IF(ISBLANK(B14), 0, IF(ISNA(VLOOKUP(B14,'3_Daftar_AHSP'!A:E,5,FALSE)), 0, VLOOKUP(B14,'3_Daftar_AHSP'!A:E,5,FALSE))) | G14: =IF(ISNUMBER(E14),E14*F14,0)
A15: 11 | C15: =IF(ISBLANK(B15), "", IF(ISNA(VLOOKUP(B15,'3_Daftar_AHSP'!A:E,3,FALSE)), "Kode Salah", VLOOKUP(B15,'3_Daftar_AHSP'!A:E,3,FALSE))) | D15: =IF(ISBLANK(B15), "", IF(ISNA(VLOOKUP(B15,'3_Daftar_AHSP'!A:E,4,FALSE)), "", VLOOKUP(B15,'3_Daftar_AHSP'!A:E,4,FALSE))) | F15: =IF(ISBLANK(B15), 0, IF(ISNA(VLOOKUP(B15,'3_Daftar_AHSP'!A:E,5,FALSE)), 0, VLOOKUP(B15,'3_Daftar_AHSP'!A:E,5,FALSE))) | G15: =IF(ISNUMBER(E15),E15*F15,0)
A16: 12 | C16: =IF(ISBLANK(B16), "", IF(ISNA(VLOOKUP(B16,'3_Daftar_AHSP'!A:E,3,FALSE)), "Kode Salah", VLOOKUP(B16,'3_Daftar_AHSP'!A:E,3,FALSE))) | D16: =IF(ISBLANK(B16), "", IF(ISNA(VLOOKUP(B16,'3_Daftar_AHSP'!A:E,4,FALSE)), "", VLOOKUP(B16,'3_Daftar_AHSP'!A:E,4,FALSE))) | F16: =IF(ISBLANK(B16), 0, IF(ISNA(VLOOKUP(B16,'3_Daftar_AHSP'!A:E,5,FALSE)), 0, VLOOKUP(B16,'3_Daftar_AHSP'!A:E,5,FALSE))) | G16: =IF(ISNUMBER(E16),E16*F16,0)
A17: 13 | C17: =IF(ISBLANK(B17), "", IF(ISNA(VLOOKUP(B17,'3_Daftar_AHSP'!A:E,3,FALSE)), "Kode Salah", VLOOKUP(B17,'3_Daftar_AHSP'!A:E,3,FALSE))) | D17: =IF(ISBLANK(B17), "", IF(ISNA(VLOOKUP(B17,'3_Daftar_AHSP'!A:E,4,FALSE)), "", VLOOKUP(B17,'3_Daftar_AHSP'!A:E,4,FALSE))) | F17: =IF(ISBLANK(B17), 0, IF(ISNA(VLOOKUP(B17,'3_Daftar_AHSP'!A:E,5,FALSE)), 0, VLOOKUP(B17,'3_Daftar_AHSP'!A:E,5,FALSE))) | G17: =IF(ISNUMBER(E17),E17*F17,0)
... A34: 30 | C34: =IF(ISBLANK(B34), "", IF(ISNA(VLOOKUP(B34,'3_Daftar_AHSP'!A:E,3,FALSE)), "Kode Salah", VLOOKUP(B34,'3_Daftar_AHSP'!A:E,3,FALSE))) | D34: =IF(ISBLANK(B34), "", IF(ISNA(VLOOKUP(B34,'3_Daftar_AHSP'!A:E,4,FALSE)), "", VLOOKUP(B34,'3_Daftar_AHSP'!A:E,4,FALSE))) | F34: =IF(ISBLANK(B34), 0, IF(ISNA(VLOOKUP(B34,'3_Daftar_AHSP'!A:E,5,FALSE)), 0, VLOOKUP(B34,'3_Daftar_AHSP'!A:E,5,FALSE))) | G34: =IF(ISNUMBER(E34),E34*F34,0)
A35: TOTAL BIAYA KONSTRUKSI (RAB DETAIL) | G35: =SUM(G5:G34)

Sheet 3_Daftar_AHSP
A1: DAFTAR HARGA SATUAN PEKERJAAN (AHSP SE BINKON 182/2025)
A2: No | B2: Kode AHSP | C2: Uraian Pekerjaan | D2: Satuan | E2: Harga Satuan Total (Rp)
A3: 1 | B3: 1.1.1.1 | C3: Pembuatan 1 m’ pagar sementara dari kayu tinggi 2 meter | D3: m' | E3: 787397
A4: 2 | B4: 1.1.1.2 | C4: Pembuatan 1 m’ pagar sementara dari seng gelombang rangka kayu tinggi 2 meter | D4: m' | E4: 635526
A5: 3 | B5: 1.1.1.3 | C5: Pembuatan 1 m’ pagar sementara dari kawat duri tinggi 2 meter | D5: m' | E5: 378239
A6: 4 | B6: 1.1.1.4 | C6: Pembuatan 1 m’ pagar sementara seng gelombang rangka baja L.40.40.4 tinggi pagar 1.8 meter | D6: m' | E6: 428906
A7: 5 | B7: 1.1.1.5 | C7: Pembuatan 1 m2 pagar BRC Galvanis | D7: m2 | E7: 17431
A8: 6 | B8: 1.1.1.6 | C8: Pemasangan 1 m2 panel beton pracetak 50x50x240 untuk pagar | D8: m2 | E8: 484982
A9: 7 | B9: 1.1.2 | C9: Alat dan/atau sarana penunjang | E9: 0
A10: 8 | B10: 1.1.2.1 | C10: 1 buah papan nama pekerjaan ukuran 0.8x1.2 menggunakan multiflex 18 mm, frame besi siku dan tiang kayu 8/12 | D10: buah | E10: 1909085
A11: 9 | B11: 1.1.2.2 | C11: 1 buah papan nama pekerjaan ukuran 0.6x08 menggunakan multiplex 10 mm, frame allumunium siku dan tiang kayu 5/7, printing banner plastik | D11: buah | E11: 702576
A12: 10 | B12: 1.1.2.3 | C12: Pembuatan 1 m2 kantor sementara/rumah jaga/gudang semen dan peralatan lantai plesteran, dinding setengah tembok | D12: m2 | E12: 3501283
A13: 11 | B13: 1.1.2.4 | C13: Pembuatan 1 m2 direksi keet (Kantor), los kerja dan gudang | D13: m2 | E13: 5699688
A14: 12 | B14: 1.1.2.5 | C14: Pembuatan 1 m2 jalan sementara lapis macadam | D14: m2 | E14: 1368398
A15: 13 | B15: 1.1.2.6 | C15: Pembuatan 1 m2 jalan sementara (Jalan Tanah) | D15: m2 | E15: 1281336
A16: 14 | B16: 1.1.2.7 | C16: Pembuatan 1 m2 jalan sementara (Jalan Kerikil) | D16: m2 | E16: 1343259
A17: 15 | B17: 1.1.3.1 | C17: 1 m3 Pembersihan dan pengupasan permukaan tanah (striping) s.d. tanaman ∅ 2 cm | D17: m2 | E17: 12100
A18: 16 | B18: 1.1.3.2 | C18: Tebas tebang 1 m2 tanaman/tumbuhan ∅ < 5 cm | D18: m2 | E18: 3960
A19: 17 | B19: 1.1.3.3. | C19: Tebas tebang 1 m 2 tanaman/tumbuhan ∅ >5 s.d. 15 cm | D19: m2 | E19: 6600
A20: 18 | B20: 1.1.3.4 | C20: Tebas tebang 1 batang pohon/tumbuhan ∅ >15 s.d. 30 cm | D20: btg | E20: 22341
A21: 19 | B21: 1.1.3.5 | C21: Tebas tebang 1 batang pohon/tumbuhan ∅ > 30 s.d 50 cm | D21: btg | E21: 22209
... A33: 31 | B33: 1.1.3.17 | C33: Gali dan cabut 1 tunggul pohon tanaman keras ∅ > 75 cm (termasuk pembuangan sisa tunggul dengan menutup kembali bekas lubang) | D33: m' | E33: 271920
A34: 32 | B34: 1.1.4 | C34: Pengukuran dan Pasangan Bouwplank | E34: 0
A35: 33 | B35: 1.1.4.1 | C35: Pengukuran ulang topografi seluas 1 Ha | D35: Ha | E35: 3277091
A36: 34 | B36: 1.1.4.2 | C36: Pasangan 1 m' bouwplank | D36: m' | E36: 171528
A37: 35 | B37: 1.1.4.3 | C37: Patok Kayu (kaso5/7) Panjang 0,5 m' | D37: m' | E37: 191337
A38: 36 | B38: 1.1.4.4 | C38: 1 Buah Patok Kayu (Kaso 5/7) panjang 1 m' | D38: m' | E38: 85540
A39: 37 | B39: 1.1.4.5 | C39: Patok Tetap Bantu (PTB) | D39: m' | E39: 144262
A40: 38 | B40: 1.1.4.6 | C40: Patok Tetap Utama (PTU) | D40: m' | E40: 215837
A41: 39 | B41: 1.2.1.1.1 | C41: Penggalian 1 m3 tanah biasa sedalam 0 s.d. 1 m untuk volume s.d. 200 m3 secara manual | D41: m3 | E41: 90860
A42: 40 | B42: 1.2.1.1.2 | C42: Penggalian 1 m3 tanah biasa sedalam 0 s.d. 1 m untuk volume 200 m3 s.d 2.000 m3 secara manual | D42: m3 | E42: 74316
A43: 41 | B43: 1.2.1.1.3 | C43: Penggalian 1 m3 tanah biasa sedalam 0 s.d. 1 m untuk volume > 2.000 m3 secara Manual | D43: m3 | E43: 52800
A44: 42 | B44: 1.2.1.1.4 | C44: Penggalian 1 m3 tanah biasa sedalam > 1 s.d. 2 m untuk volume s.d 200 m3 secara manual | D44: m3 | E44: 108900
A45: 43 | B45: 1.2.1.1.5 | C45: Penggalian 1 m3 tanah biasa sedalam > 1 s.d. 2 m untuk volume > 200 m3 secara manual | D45: m3 | E45: 89100
A46: 44 | B46: 1.2.1.1.6 | C46: Penggalian 1 m3 tanah biasa sedalam > 2 s.d. 3 m untuk volume s.d 200 m3 secara manual | D46: m3 | E46: 130240
... A645: 643 | B645: 3.11.2.4 | C645: Pemasangan 1 buah Jendela Kaca Upvc 1 daun ukuran 0,79 x 1,30 m | D645: buah | E645: 2224568
A646: 644 | B646: 3.11.3.1 | C646: Pemasangan 1 m' kusen aluminium | E646: 175583
A647: 645 | B647: 3.11.3.2 | C647: Pembuatan dan pemasangan 1 m’ kusen pintu dan kusen jendela, kayu kelas I uk. 6x12 cm | D647: m' | E647: 312778
A648: 646 | B648: 3.11.3.3 | C648: Pembuatan dan pemasangan 1 m’ kusen pintu dan kusen jendela, kayu kelas I uk. 6x15 cm | D648: m' | E648: 373278
A649: 647 | B649: 3.11.3.4 | C649: Pembuatan dan pemasangan 1 m’ kusen pintu dan kusen jendela, kayu kelas II atau III uk. 6x12 cm | D649: m' | E649: 189325
...

Sheet 4_Detail_AHSP
A1: DETAIL URAIAN ANALISA HARGA SATUAN PEKERJAAN (AHSP)
A2: Tabel ini merinci komposisi bahan, alat, dan pekerja untuk setiap kode AHSP
A4: KODE: 1.1.1.1 - Pembuatan 1 m’ pagar sementara dari kayu tinggi 2 meter
A5: No | B5: Uraian Komponen | C5: Satuan | D5: Koef | E5: Harga Satuan (Rp) | F5: Jumlah Harga (Rp)
A6: 1 | B6: Pekerja OH | C6: 0.6 | D6: 100000 | E6: 60000 | F6: 0.1
A7: 2 | B7: Tukang kayu | C7: OH | D7: 0.2 | E7: 145000 | F7: 29000
A8: 3 | B8: Tukang batu | C8: OH | D8: 0.2 | E8: 145000 | F8: 29000
A9: 4 | B9: Kepala tukang | C9: OH | D9: 0.04 | E9: 175000 | F9: 7000
A10: 5 | B10: Mandor | C10: OH | D10: 0.013 | E10: 200000 | F10: 2600
A11: 1 | B11: Kaso 5/7 kayu kelas II | C11: m3 | D11: 0.0387 | E11: 10214200 | F11: 395289.54
A12: 2 | B12: Papan Kayu ukuran 2/20 cm | C12: m3 | D12: 0.0396 | E12: 2500000 | F12: 99000
A13: 3 | B13: Paku biasa 5 inchi | C13: kg | D13: 0.5872 | E13: 20000 | F13: 11744
A14: 4 | B14: Semen Portland (PC) | C14: kg | D14: 26.406 | E14: 1300 | F14: 34327.8
A15: 5 | B15: Pasir Beton | C15: kg | D15: 61.56 | E15: 300 | F15: 18468
A16: 6 | B16: Kerikil | C16: kg | D16: 83.349 | E16: 210 | F16: 17503.29
A17: 7 | B17: Air | C17: liter | D17: 17.415 | E17: 200 | F17: 3483
A18: 8 | B18: Residu | C18: liter | D18: 0.4 | E18: 21000 | F18: 8400
D19: SUBTOTAL UPAH | F19: 127600
D20: SUBTOTAL BAHAN | F20: 588215.63
D21: SUBTOTAL ALAT | F21: 0
E22: TOTAL HARGA SATUAN (Inc. Overhead) | F22: 787397
A24: KODE: 1.1.1.2 - Pembuatan 1 m’ pagar sementara dari seng gelombang rangka kayu tinggi 2 meter
A25: No | B25: Uraian Komponen | C25: Satuan | D25: Koef | E25: Harga Satuan (Rp) | F25: Jumlah Harga (Rp)
A26: 1 | B26: Pekerja | C26: OH | D26: 0.25 | E26: 100000 | F26: 25000
A27: 2 | B27: Tukang kayu | C27: OH | D27: 0.125 | E27: 145000 | F27: 18125
A28: 3 | B28: Tukang batu | C28: OH | D28: 0.125 | E28: 145000 | F28: 18125
A29: 4 | B29: Kepala tukang | C29: OH | D29: 0.025 | E29: 175000 | F29: 4375
A30: 5 | B30: Mandor | C30: OH | D30: 0.008 | E30: 200000 | F30: 1600
A31: 1 | B31: Kaso 5/7 kayu kelas II | C31: m3 | D31: 0.031 | E31: 10214200 | F31: 316640.2
A32: 2 | B32: Seng gelombang | C32: lembar | D32: 1.3125 | E32: 85000 | F32: 111562.5
A33: 3 | B33: Paku biasa 5 inchi | C33: kg | D33: 0.4271 | E33: 20000 | F33: 8542
A34: 4 | B34: Semen Portland (PC) | C34: kg | D34: 26.406 | E34: 1300 | F34: 34327.8
A35: 5 | B35: Pasir beton | C35: kg | D35: 61.56 | E35: 300 | F35: 18468
A36: 6 | B36: Kerikil | C36: kg | D36: 83.349 | E36: 210 | F36: 17503.29
A37: 7 | B37: Air | C37: liter | D37: 17.415 | E37: 200 | F37: 3483
D38: SUBTOTAL UPAH | F38: 67225
D39: SUBTOTAL BAHAN | F39: 510526.79
D40: SUBTOTAL ALAT | F40: 0
E41: TOTAL HARGA SATUAN (Inc. Overhead) | F41: 635526
A43: KODE: 1.1.1.3 - Pembuatan 1 m’ pagar sementara dari kawat duri tinggi 2 meter
...

Sheet 5_Analisa_Alat
A1: DATABASE HARGA SEWA ALAT (STANDAR CIPTA KARYA)
A2: Daftar ini memuat seluruh alat berat & sewa mesin yang diekstrak dari Database Cipta Karya
A4: No | B4: Uraian Alat | C4: Satuan | D4: Harga Sewa Cipta Karya (Rp)
A5: 1 | B5: Sewa Tripot | C5: hari | D5: 108000
A6: 2 | B6: Gergaji Pipa | C6: hari | D6: 32500
A7: 3 | B7: Peralatan potong pipa T1/manual (gergaji) / saw | C7: hari | D7: 35000
A8: 4 | B8: Cilinder Saw | C8: hari | D8: 75000
A9: 5 | B9: Peralatan potong pipa T2/mekanik / cilinder saw | C9: hari | D9: 75000
A10: 6 | B10: Butt Fushion dan Genset | C10: hari | D10: 2500000
A11: 7 | B11: Compressor | C11: jam | D11: 92500
A12: 8 | B12: Asphalt Distributor | C12: jam | D12: 307300
A13: 9 | B13: Asphalt finisher | C13: jam | D13: 602500
A14: 10 | B14: Asphalt liquid mixer 1000 ℓ | C14: jam | D14: 61100
A15: 11 | B15: Asphalt mixing plant | C15: jam | D15: 6253800
A16: 12 | B16: Asphalt sprayer 850 ℓ | C16: jam | D16: 74900
... A152: 148 | B152: Truck Crane 5 ton | C152: jam | D152: 525000
A155: KALKULATOR PENYUSUTAN & BIAYA OPERASI ALAT BARU
A156: No | B156: Nama Alat | C156: Harga Pokok (Rp) | D156: Jam/Thn | E156: BBM (L/Jam) | F156: Penyusutan/Jam | G156: Opr/Jam | H156: Total Sewa/Jam
A157: 1 | B157: Excavator Custom | C157: 1200000000 | D157: 2000 | E157: 15 | F157: =((C157-0.1*C157)*0.15)/D157 | G157: =(E157*12000)+((0.125*C157)/D157) | H157: =F157+G157

Sheet 6_Analisa_SMKK
A1: ANALISA KESELAMATAN KONSTRUKSI (SMKK)
A2: No | B2: Rincian Item K3 | C2: Satuan | D2: Kuantitas | E2: Harga Satuan (Rp) | F2: Total (Rp)
B3: A. | C3: Sub total Penyiapan Dokumen penerapan SMKK
A4: 2 | B4: Sosialisasi, Promosi dan Pelatihan
B5: a | C5: Induksi Keselamatan Konstruksi (Safety Induction) | D5: Kegiatan
B6: b | C6: Pengarahan Keselamatan Konstruksi (Safety Briefing) (khusus untuk pekerja) | D6: Kegiatan
B7: c | C7: Pertemuan keselamatan (Safety Talk) (khusus untuk pekerja) | D7: Kegiatan
B8: d | C8: Tool Box Meeting
B9: e | C9: Rapat keselamatan konstruksi (Construction Safety Meeting) | D9: Kegiatan
B10: f | C10: Pelatihan kepedulian/ kesadaran (awareness) Keselamatan Konstruksi, antara lain:
B11: g | C11: Sosialisasi/penyuluhan HIV/AIDS/pencegahan penyakit menular | D11: Kegiatan
B12: h | C12: Simulasi Keselamatan Konstruksi (tanggap darurat) | D12: Kegiatan
B13: i | C13: Spanduk (banner) | D13: Lembar
B14: j | C14: Poster/leaflet | D14: Lembar
B15: k | C15: Papan Informasi Keselamatan konstruksi | D15: Bh
B16: B | C16: Subtotal Sosialisasi, Promosi dan Pelatihan
A17: 3 | B17: Alat Pelindung Kerja dan Alat Pelindung Diri
B18: a | C18: APK, antara lain :
B19: 1) | C19: 1) Jaring pengaman (safety net) | D19: m2
B20: b | C20: APD, antara lain :
B21: C | C21: Subtotal Alat Pelindung Kerja dan Alat Pelindung Diri
A22: 4 | B22: Asuransi:
B23: a | C23: Asuransi (Construction All Risk/CAR) | D23: Ls
B24: D | C24: Subtotal Asuransi
A25: 5 | B25: Personel Keselamatan Konstruksi:
B26: a | C26: Ahli K3 Konstruksi atau Ahli Keselamatan Konstruksi | D26: Org/Bln
B27: b | C27: Petugas Keselamatan Konstruksi atau Petugas K3 Konstruksi | D27: Org/Bln
B28: c | C28: Petugas tanggap darurat | D28: Org/Bln
B29: d | C29: Petugas pemadam kebakaran | D29: Org/Bln
B30: e | C30: Petugas P3K | D30: Org/Bln
B31: f | C31: Petugas pengatur lalu lintas/flagman | D31: Org/Bln
B32: g | C32: Tenaga medis dan/atau kesehatan (Dokter) | D32: Org/Bln
B33: h | C33: Petugas paramedis | D33: Org/Bln
B34: i | C34: Petugas pengelolaan lingkungan/petugas pengelola limbah B3 | D34: Org/Bln
B35: j | C35: Petugas pengelolaan lingkungan/petugas pengelola limbah B3 | D35: Org/Bln
B36: E | C36: Subtotal Personel Keselamatan Konstruksi
A37: 6 | B37: Fasilitas Sarana, Prasarana, dan Alat Kesehatan:
B38: a | C38: Peralatan P3K (Kotak P3K, Alat pengukur suhu badan, tandu, obat luka, dll) | D38: Set
B39: b | C39: Ruang P3K/Klinik | D39: Unit
B40: c | C40: Peralatan Pengasapan (Obat dan mesin fogging) | D40: Unit
...

Sheet 7_Database_Upah
A1: DATABASE UPAH PEKERJA (SE BINKON 182/2025)
A2: No | B2: Kode | C2: Jenis Pekerja | D2: Satuan | E2: Harga Upah (Rp)
A3: 1 | B3: L.01 | C3: Pekerja | D3: OH | E3: 100000
A4: 2 | B4: L.02 | C4: Tukang batu | D4: OH | E4: 145000
A5: 3 | B5: L.02 | C5: Tukang kayu | D5: OH | E5: 145000
A6: 4 | B6: L.02 | C6: Tukang besi | D6: OH | E6: 145000
A7: 5 | B7: L.02 | C7: Tukang cat | D7: OH | E7: 145000
B8: L.02 | C8: Tukang pelitur | D8: OH | E8: 145000
A9: 6 | B9: L.02 | C9: Tukang pipa | D9: OH | E9: 145000
A10: 7 | B10: L.02 | C10: Tukang penganyam bronjong | D10: OH | E10: 145000
A11: 8 | B11: L.02 | C11: Tukang tebas | D11: OH | E11: 145000
A12: 9 | B12: L.02 | C12: Tukang las | D12: OH | E12: 145000
A13: 10 | B13: L.02 | C13: Tukang las geotextile | D13: OH | E13: 145000
A14: 11 | B14: L.02 | C14: Tukang listrik | D14: OH | E14: 145000
A15: 12 | B15: L.02 | C15: Tukang alumunium | D15: OH | E15: 145000
A16: 13 | B16: L.02 | C16: Tukang kaca | D16: OH
A17: 14 | B17: L.02 | C17: Tukang erection | D17: OH | E17: 145000
A18: 15 | B18: L.02 | C18: Tukang tanam | D18: OH | E18: 145000
C19: Tukang Tanam | D19: OH | E19: 181250
C20: Kepala Tukang Tanam | D20: OH | E20: 218750
C21: Tukang pemelihara taman | D21: OH | E21: 145000
C22: Tukang pemelihara taman (115% Pekerja) | D22: OH | E22: 115000
A23: 10 | C23: Tukang gali | D23: OH | E23: 120000
A24: 11 | C24: Tukang aspal | D24: OH | E24: 120000
A25: 13 | B25: L.03 | C25: Kepala tukang | D25: OH | E25: 175000
A26: 14 | B26: L.04 | C26: Mandor | D26: OH | E26: 200000
A27: 21 | B27: L.05 | C27: Juru ukur | D27: OH | E27: 175000
A28: 28 | B28: L.06 | C28: Pembantu juru ukur | D28: OH | E28: 150000
A29: 24 | B29: L.07 | C29: Mekanik alat berat | D29: OH | E29: 220000
A30: 25 | B30: L.08 | C30: Operator alat berat | D30: OH | E30: 250000
A31: 30 | B31: L.09 | C31: Pembantu operator alat berat | D31: OH | E31: 130000
A32: 31 | B32: L.10 | C32: Sopir | D32: OH | E32: 200000
A33: 22 | B33: L.11 | C33: Kenek | D33: OH | E33: 135000
A34: 15 | C34: Administrasi bor | D34: OH | E34: 110000
A35: 16 | C35: Ahli geologist | D35: OH | E35: 400000
A36: 17 | C36: Ahli topografi | D36: OH | E36: 400000
A37: 18 | C37: Crew driller | D37: OH | E37: 125000
A38: 19 | C38: Driller | D38: OH | E38: 140000
A39: 20 | C39: Juru gambar | D39: OH | E39: 150000
A40: 23 | C40: Koordinator driller | D40: OH | E40: 155000
...

Sheet 8_Database_Material
A1: DATABASE BAHAN MATERIAL (SE BINKON 182/2025)
A2: No | B2: Kode | C2: Nama Material | D2: Satuan | E2: Harga Material (Rp)
A3: NO | B3: Kode | C3: UPAH - MATERIAL - ALAT | D3: SATUAN
A4: 1 | C4: 2 | D4: 3 | E4: 4
A5: I. | C5: UPAH
A6: II. | C6: MATERIAL
C7: MATERIAL TANAH DAN BATUAN
A8: 1 | C8: Agregat kasar | D8: m3 | E8: 385000
C9: Agregar Kasar | D9: kg | E9: 226.47059
C10: Agg Pokok | D10: m3 | E10: 350000
C11: Agg Pengunci | D11: m3 | E11: 360000
C12: Agg Penutup | D12: m3 | E12: 370000
A13: 2 | C13: Bata merah | D13: buah | E13: 700
A14: 3 | C14: Bata merah 5 x 11 x 22 cm (per m3) | D14: m3 | E14: 590000
A15: 4 | C15: Bata ringan | D15: m3 | E15: 703500
A16: 5 | C16: Bata ringan t=10 cm | D16: m3 | E16: 685800
A17: 6 | C17: Bata ringan tebal 10 cm | D17: buah | E17: 11000
A18: 7 | C18: Bata ringan tebal 20 cm | D18: buah | E18: 20000
A19: 8 | C19: Bata ringan tebal 7,5 cm | D19: buah | E19: 8500
A20: 9 | C20: Bata rooster | D20: buah | E20: 15000
C21: Bata Berongga Uk. 12x11x24 | D21: buah | E21: 15000
A22: 10 | C22: Batu alam andesit bakar | D22: m² | E22: 179300
A23: 11 | C23: Batu alam andesit non bakar | D23: m² | E23: 177500
A24: 12 | C24: Batu belah (base camp - lokasi pekerjaan) | D24: m3 | E24: 339861
A25: 13 | C25: Batu belah (quarry - base camp) | D25: m3 | E25: 235000
A26: 14 | C26: Batu belah (quarry - lokasi pekerjaan) | D26: m3 | E26: 286500
C27: Pasangan batu ukuran 20/50 t=40cm | D27: m3 | E27: 286500
C28: Fondasi pasangan batu | D28: m3 | E28: 286500
A29: 15 | C29: Batu belah (quarry) | D29: m3 | E29: 127500
A30: 16 | C30: Batu candi | D30: m² | E30: 152000
A31: 17 | C31: Batu kali (quarry - base camp) | D31: m3 | E31: 187400
A32: 18 | C32: Batu kali (quarry) | D32: m3 | E32: 142500
A33: 19 | C33: Batu Muka ukuran 12x18 cm | D33: m2 | E33: 97500
C34: Batu | D34: m3 | E34: 97500
A35: 20 | C35: Batu paras | D35: m3 | E35: 125000
A36: 21 | C36: Batu pecah | D36: kg | E36: 210
A37: 22 | C37: Batu pecah 3/5 | D37: m3 | E37: 363800
A38: 23 | C38: Batu pecah 5/7 | D38: m3 | E38: 351800
A39: 24 | C39: Batu putih | D39: m² | E39: 123000
A40: 25 | C40: Batu putih breksi | D40: m² | E40: 117700
...
